Workbook

Sheet Raw_Data
A1: Req_ID | B1: Client_Name | C1: Industry | D1: Role | E1: Seniority_Level | F1: Recruiter_Name | G1: Region | H1: Sourcing_Channel | I1: Date_Sourced | J1: Date_Submitted | K1: Date_Interview | L1: Date_Offer | M1: Date_Joined | N1: Candidate_Name | O1: Gender | P1: Experience_Yrs | Q1: Current_CTC_LPA | R1: Expected_CTC_LPA | S1: Offered_CTC_LPA | T1: Location | U1: Interview_Status | V1: Offer_Status | W1: Joining_Status | X1: Notice_Period_Days | Y1: TAT_Days | Z1: sourced_month | AA1: Joined_month
A2: REQ001 | B2: TCS | C2: IT Services | D2: Data Analyst | E2: Junior | F2: Senthil Kumar | G2: South | H2: LinkedIn | I2: 2025-01-05 | J2: 2025-01-07 | K2: 2025-01-12 | L2: 2025-01-15 | M2: 2025-01-20 | N2: Aravind Kumar | O2: Male | P2: 3 | Q2: 5 | R2: 6.5 | S2: 6.5 | T2: Chennai | U2: Selected | V2: Accepted | W2: Joined | X2: 30 | Y2: 15 | Z2: =TEXT(Table1[[#This Row],[Date_Sourced]],"mmm - YYYY") -> Jan - 2025 | AA2: =TEXT(Table1[[#This Row],[Date_Joined]],"mmm - YYYY") -> Jan - 2025
A3: REQ002 | B3: Infosys | C3: IT Services | D3: MIS Analyst | E3: Junior | F3: Anitha R | G3: South | H3: Naukri | I3: 2025-01-06 | J3: 2025-01-09 | K3: 2025-01-14 | N3: Priya Sharma | O3: Female | P3: 2 | Q3: 4 | R3: 5 | S3: 0 | T3: Bangalore | U3: In-Progress | V3: Pending | W3: Not Joined | X3: 60 | Y3: 0 | Z3: =TEXT(Table1[[#This Row],[Date_Sourced]],"mmm - YYYY") -> Jan - 2025 | AA3: =TEXT(Table1[[#This Row],[Date_Joined]],"mmm - YYYY") -> Jan - 1900
A4: REQ003 | B4: Wipro | C4: IT Services | D4: Business Analyst | E4: Mid | F4: Senthil Kumar | G4: South | H4: Referral | I4: 2025-01-08 | J4: 2025-01-10 | K4: 2025-01-15 | N4: Ravi Teja | O4: Male | P4: 4 | Q4: 6.5 | R4: 8 | S4: 0 | T4: Hyderabad | U4: Rejected | W4: Not Joined | X4: 30 | Y4: 0 | Z4: =TEXT(Table1[[#This Row],[Date_Sourced]],"mmm - YYYY") -> Jan - 2025 | AA4: =TEXT(Table1[[#This Row],[Date_Joined]],"mmm - YYYY") -> Jan - 1900
A5: REQ004 | B5: HCL | C5: IT Services | D5: Data Engineer | E5: Senior | F5: Ramesh Gupta | G5: North | H5: LinkedIn | I5: 2025-01-10 | J5: 2025-01-13 | K5: 2025-01-18 | L5: 2025-01-22 | M5: 2025-01-28 | N5: Sneha Nair | O5: Female | P5: 5 | Q5: 10 | R5: 12 | S5: 12 | T5: Mumbai | U5: Selected | V5: Accepted | W5: Joined | X5: 15 | Y5: 18 | Z5: =TEXT(Table1[[#This Row],[Date_Sourced]],"mmm - YYYY") -> Jan - 2025 | AA5: =TEXT(Table1[[#This Row],[Date_Joined]],"mmm - YYYY") -> Jan - 2025
A6: REQ005 | B6: Cognizant | C6: IT Services | D6: MIS Analyst | E6: Junior | F6: Anitha R | G6: South | H6: Naukri | I6: 2025-01-12 | J6: 2025-01-15 | N6: Karthik Raj | O6: Male | P6: 1 | Q6: 3 | R6: 3.5 | S6: 0 | T6: Chennai | U6: In-Progress | V6: Pending | W6: Not Joined | X6: 0 | Y6: 0 | Z6: =TEXT(Table1[[#This Row],[Date_Sourced]],"mmm - YYYY") -> Jan - 2025 | AA6: =TEXT(Table1[[#This Row],[Date_Joined]],"mmm - YYYY") -> Jan - 1900
A7: REQ006 | B7: Accenture | C7: Consulting | D7: Data Analyst | E7: Mid | F7: Kavitha M | G7: West | H7: LinkedIn | I7: 2025-01-15 | J7: 2025-01-17 | K7: 2025-01-22 | L7: 2025-01-25 | M7: 2025-02-01 | N7: Divya Menon | O7: Female | P7: 3 | Q7: 5.5 | R7: 7 | S7: 7 | T7: Pune | U7: Selected | V7: Accepted | W7: Joined | X7: 45 | Y7: 17 | Z7: =TEXT(Table1[[#This Row],[Date_Sourced]],"mmm - YYYY") -> Jan - 2025 | AA7: =TEXT(Table1[[#This Row],[Date_Joined]],"mmm - YYYY") -> Feb - 2025
A8: REQ007 | B8: TCS | C8: IT Services | D8: Reporting Analyst | E8: Junior | F8: Senthil Kumar | G8: South | H8: Walk-In | I8: 2025-01-18 | J8: 2025-01-20 | K8: 2025-01-25 | N8: Anbu Selvan | O8: Male | P8: 2 | Q8: 3.5 | R8: 4.5 | S8: 0 | T8: Tiruchirappalli | U8: In-Progress | V8: Pending | W8: Not Joined | X8: 30 | Y8: 0 | Z8: =TEXT(Table1[[#This Row],[Date_Sourced]],"mmm - YYYY") -> Jan - 2025 | AA8: =TEXT(Table1[[#This Row],[Date_Joined]],"mmm - YYYY") -> Jan - 1900
A9: REQ008 | B9: Deloitte | C9: Consulting | D9: Data Scientist | E9: Senior | F9: Ramesh Gupta | G9: North | H9: LinkedIn | I9: 2025-01-20 | J9: 2025-01-22 | K9: 2025-01-28 | N9: Meera Pillai | O9: Female | P9: 6 | Q9: 15 | R9: 18 | S9: 0 | T9: Bangalore | U9: Rejected | W9: Not Joined | X9: 60 | Y9: 0 | Z9: =TEXT(Table1[[#This Row],[Date_Sourced]],"mmm - YYYY") -> Jan - 2025 | AA9: =TEXT(Table1[[#This Row],[Date_Joined]],"mmm - YYYY") -> Jan - 1900
A10: REQ009 | B10: Infosys | C10: IT Services | D10: MIS Analyst | E10: Junior | F10: Anitha R | G10: South | H10: Naukri | I10: 2025-01-22 | J10: 2025-01-24 | K10: 2025-01-29 | L10: 2025-02-02 | M10: 2025-02-10 | N10: Suresh Babu | O10: Male | P10: 1 | Q10: 2.5 | R10: 3 | S10: 3 | T10: Coimbatore | U10: Selected | V10: Accepted | W10: Joined | X10: 0 | Y10: 19 | Z10: =TEXT(Table1[[#This Row],[Date_Sourced]],"mmm - YYYY") -> Jan - 2025 | AA10: =TEXT(Table1[[#This Row],[Date_Joined]],"mmm - YYYY") -> Feb - 2025
A11: REQ010 | B11: HCL | C11: IT Services | D11: Business Analyst | E11: Mid | F11: Kavitha M | G11: West | H11: Referral | I11: 2025-01-25 | J11: 2025-01-28 | K11: 2025-02-03 | N11: Lakshmi Priya | O11: Female | P11: 3 | Q11: 6 | R11: 7.5 | S11: 0 | T11: Chennai | U11: In-Progress | V11: Pending | W11: Not Joined | X11: 30 | Y11: 0 | Z11: =TEXT(Table1[[#This Row],[Date_Sourced]],"mmm - YYYY") -> Jan - 2025 | AA11: =TEXT(Table1[[#This Row],[Date_Joined]],"mmm - YYYY") -> Jan - 1900
A12: REQ011 | B12: Wipro | C12: IT Services | D12: Data Analyst | E12: Mid | F12: Senthil Kumar | G12: South | H12: LinkedIn | I12: 2025-02-01 | J12: 2025-02-04 | K12: 2025-02-09 | L12: 2025-02-13 | M12: 2025-02-18 | N12: Vijay Anand | O12: Male | P12: 4 | Q12: 7 | R12: 9 | S12: 9 | T12: Hyderabad | U12: Selected | V12: Accepted | W12: Joined | X12: 15 | Y12: 17 | Z12: =TEXT(Table1[[#This Row],[Date_Sourced]],"mmm - YYYY") -> Feb - 2025 | AA12: =TEXT(Table1[[#This Row],[Date_Joined]],"mmm - YYYY") -> Feb - 2025
A13: REQ012 | B13: Cognizant | C13: IT Services | D13: Reporting Analyst | E13: Junior | F13: Anitha R | G13: South | H13: Naukri | I13: 2025-02-03 | J13: 2025-02-06 | K13: 2025-02-11 | N13: Nithya Devi | O13: Female | P13: 2 | Q13: 3 | R13: 4 | S13: 0 | T13: Madurai | U13: In-Progress | V13: Pending | W13: Not Joined | X13: 30 | Y13: 0 | Z13: =TEXT(Table1[[#This Row],[Date_Sourced]],"mmm - YYYY") -> Feb - 2025 | AA13: =TEXT(Table1[[#This Row],[Date_Joined]],"mmm - YYYY") -> Jan - 1900
A14: REQ013 | B14: TCS | C14: IT Services | D14: Data Engineer | E14: Senior | F14: Ramesh Gupta | G14: North | H14: LinkedIn | I14: 2025-02-05 | J14: 2025-02-08 | K14: 2025-02-13 | L14: 2025-02-17 | M14: 2025-02-24 | N14: Harish M | O14: Male | P14: 5 | Q14: 12 | R14: 15 | S14: 14.5 | T14: Bangalore | U14: Selected | V14: Accepted | W14: Joined | X14: 60 | Y14: 19 | Z14: =TEXT(Table1[[#This Row],[Date_Sourced]],"mmm - YYYY") -> Feb - 2025 | AA14: =TEXT(Table1[[#This Row],[Date_Joined]],"mmm - YYYY") -> Feb - 2025
A15: REQ014 | B15: Accenture | C15: Consulting | D15: MIS Analyst | E15: Mid | F15: Kavitha M | G15: West | H15: Referral | I15: 2025-02-08 | J15: 2025-02-11 | K15: 2025-02-16 | N15: Pooja Iyer | O15: Female | P15: 3 | Q15: 5 | R15: 6 | S15: 0 | T15: Chennai | U15: Rejected | W15: Not Joined | X15: 30 | Y15: 0 | Z15: =TEXT(Table1[[#This Row],[Date_Sourced]],"mmm - YYYY") -> Feb - 2025 | AA15: =TEXT(Table1[[#This Row],[Date_Joined]],"mmm - YYYY") -> Jan - 1900
A16: REQ015 | B16: Infosys | C16: IT Services | D16: Data Analyst | E16: Junior | F16: Senthil Kumar | G16: South | H16: Naukri | I16: 2025-02-10 | J16: 2025-02-13 | K16: 2025-02-18 | L16: 2025-02-21 | M16: 2025-02-26 | N16: Balaji S | O16: Male | P16: 2 | Q16: 4.5 | R16: 5.5 | S16: 5.5 | T16: Tiruchirappalli | U16: Selected | V16: Accepted | W16: Joined | X16: 0 | Y16: 16 | Z16: =TEXT(Table1[[#This Row],[Date_Sourced]],"mmm - YYYY") -> Feb - 2025 | AA16: =TEXT(Table1[[#This Row],[Date_Joined]],"mmm - YYYY") -> Feb - 2025
A17: REQ016 | B17: HCL | C17: IT Services | D17: MIS Analyst | E17: Junior | F17: Anitha R | G17: South | H17: Walk-In | I17: 2025-02-12 | J17: 2025-02-15 | K17: 2025-02-20 | L17: 2025-02-24 | M17: 2025-03-03 | N17: Rekha V | O17: Female | P17: 2 | Q17: 4 | R17: 5 | S17: 5 | T17: Bangalore | U17: Selected | V17: Accepted | W17: Joined | X17: 30 | Y17: 19 | Z17: =TEXT(Table1[[#This Row],[Date_Sourced]],"mmm - YYYY") -> Feb - 2025 | AA17: =TEXT(Table1[[#This Row],[Date_Joined]],"mmm - YYYY") -> Mar - 2025
A18: REQ017 | B18: Wipro | C18: IT Services | D18: Data Analyst | E18: Mid | F18: Senthil Kumar | G18: South | H18: LinkedIn | I18: 2025-02-15 | J18: 2025-02-18 | K18: 2025-02-23 | N18: Dinesh P | O18: Male | P18: 3 | Q18: 5 | R18: 6 | S18: 0 | T18: Chennai | U18: Rejected | W18: Not Joined | X18: 15 | Y18: 0 | Z18: =TEXT(Table1[[#This Row],[Date_Sourced]],"mmm - YYYY") -> Feb - 2025 | AA18: =TEXT(Table1[[#This Row],[Date_Joined]],"mmm - YYYY") -> Jan - 1900
A19: REQ018 | B19: Deloitte | C19: Consulting | D19: Business Analyst | E19: Senior | F19: Kavitha M | G19: West | H19: LinkedIn | I19: 2025-02-18 | J19: 2025-02-21 | K19: 2025-02-26 | L19: 2025-03-02 | M19: 2025-03-10 | N19: Kavya R | O19: Female | P19: 4 | Q19: 7.5 | R19: 9 | S19: 9 | T19: Pune | U19: Selected | V19: Accepted | W19: Joined | X19: 30 | Y19: 20 | Z19: =TEXT(Table1[[#This Row],[Date_Sourced]],"mmm - YYYY") -> Feb - 2025 | AA19: =TEXT(Table1[[#This Row],[Date_Joined]],"mmm - YYYY") -> Mar - 2025
A20: REQ019 | B20: Cognizant | C20: IT Services | D20: Reporting Analyst | E20: Junior | F20: Senthil Kumar | G20: South | H20: Walk-In | I20: 2025-02-20 | J20: 2025-02-23 | K20: 2025-02-28 | N20: Murugan S | O20: Male | P20: 1 | Q20: 2.5 | R20: 3.5 | S20: 0 | T20: Tiruchirappalli | U20: In-Progress | V20: Pending | W20: Not Joined | X20: 0 | Y20: 0 | Z20: =TEXT(Table1[[#This Row],[Date_Sourced]],"mmm - YYYY") -> Feb - 2025 | AA20: =TEXT(Table1[[#This Row],[Date_Joined]],"mmm - YYYY") -> Jan - 1900
A21: REQ020 | B21: TCS | C21: IT Services | D21: Data Engineer | E21: Senior | F21: Ramesh Gupta | G21: North | H21: LinkedIn | I21: 2025-02-22 | J21: 2025-02-25 | K21: 2025-03-02 | L21: 2025-03-06 | M21: 2025-03-14 | N21: Aishwarya N | O21: Female | P21: 5 | Q21: 11 | R21: 14 | S21: 13.5 | T21: Hyderabad | U21: Selected | V21: Accepted | W21: Joined | X21: 60 | Y21: 20 | Z21: =TEXT(Table1[[#This Row],[Date_Sourced]],"mmm - YYYY") -> Feb - 2025 | AA21: =TEXT(Table1[[#This Row],[Date_Joined]],"mmm - YYYY") -> Mar - 2025
A22: REQ021 | B22: Infosys | C22: IT Services | D22: MIS Analyst | E22: Junior | F22: Anitha R | G22: South | H22: Naukri | I22: 2025-03-02 | J22: 2025-03-05 | K22: 2025-03-10 | N22: Saravanan K | O22: Male | P22: 2 | Q22: 3.5 | R22: 4.5 | S22: 0 | T22: Chennai | U22: In-Progress | V22: Pending | W22: Not Joined | X22: 30 | Y22: 0 | Z22: =TEXT(Table1[[#This Row],[Date_Sourced]],"mmm - YYYY") -> Mar - 2025 | AA22: =TEXT(Table1[[#This Row],[Date_Joined]],"mmm - YYYY") -> Jan - 1900
A23: REQ022 | B23: Accenture | C23: Consulting | D23: Data Analyst | E23: Mid | F23: Kavitha M | G23: West | H23: LinkedIn | I23: 2025-03-05 | J23: 2025-03-08 | K23: 2025-03-13 | L23: 2025-03-17 | M23: 2025-03-24 | N23: Brindha M | O23: Female | P23: 3 | Q23: 6 | R23: 7.5 | S23: 7.5 | T23: Bangalore | U23: Selected | V23: Accepted | W23: Joined | X23: 15 | Y23: 19 | Z23: =TEXT(Table1[[#This Row],[Date_Sourced]],"mmm - YYYY") -> Mar - 2025 | AA23: =TEXT(Table1[[#This Row],[Date_Joined]],"mmm - YYYY") -> Mar - 2025
A24: REQ023 | B24: HCL | C24: IT Services | D24: Data Scientist | E24: Senior | F24: Ramesh Gupta | G24: North | H24: LinkedIn | I24: 2025-03-08 | J24: 2025-03-11 | K24: 2025-03-16 | N24: Ganesh T | O24: Male | P24: 4 | Q24: 11 | R24: 13 | S24: 0 | T24: Mumbai | U24: Rejected | W24: Not Joined | X24: 45 | Y24: 0 | Z24: =TEXT(Table1[[#This Row],[Date_Sourced]],"mmm - YYYY") -> Mar - 2025 | AA24: =TEXT(Table1[[#This Row],[Date_Joined]],"mmm - YYYY") -> Jan - 1900
A25: REQ024 | B25: Wipro | C25: IT Services | D25: Business Analyst | E25: Mid | F25: Anitha R | G25: South | H25: Referral | I25: 2025-03-10 | J25: 2025-03-13 | K25: 2025-03-18 | L25: 2025-03-22 | M25: 2025-03-28 | N25: Swetha L | O25: Female | P25: 2 | Q25: 4.5 | R25: 5.5 | S25: 5.5 | T25: Chennai | U25: Selected | V25: Accepted | W25: Joined | X25: 0 | Y25: 18 | Z25: =TEXT(Table1[[#This Row],[Date_Sourced]],"mmm - YYYY") -> Mar - 2025 | AA25: =TEXT(Table1[[#This Row],[Date_Joined]],"mmm - YYYY") -> Mar - 2025
A26: REQ025 | B26: Cognizant | C26: IT Services | D26: Reporting Analyst | E26: Mid | F26: Senthil Kumar | G26: South | H26: Naukri | I26: 2025-03-12 | J26: 2025-03-15 | K26: 2025-03-20 | N26: Praveen J | O26: Male | P26: 3 | Q26: 4 | R26: 5 | S26: 0 | T26: Madurai | U26: In-Progress | V26: Pending | W26: Not Joined | X26: 30 | Y26: 0 | Z26: =TEXT(Table1[[#This Row],[Date_Sourced]],"mmm - YYYY") -> Mar - 2025 | AA26: =TEXT(Table1[[#This Row],[Date_Joined]],"mmm - YYYY") -> Jan - 1900
A27: REQ026 | B27: TCS | C27: IT Services | D27: Data Analyst | E27: Junior | F27: Senthil Kumar | G27: South | H27: LinkedIn | I27: 2025-03-15 | J27: 2025-03-18 | K27: 2025-03-23 | L27: 2025-03-27 | M27: 2025-04-03 | N27: Deepa S | O27: Female | P27: 2 | Q27: 4 | R27: 5 | S27: 5 | T27: Chennai | U27: Selected | V27: Accepted | W27: Joined | X27: 30 | Y27: 19 | Z27: =TEXT(Table1[[#This Row],[Date_Sourced]],"mmm - YYYY") -> Mar - 2025 | AA27: =TEXT(Table1[[#This Row],[Date_Joined]],"mmm - YYYY") -> Apr - 2025
A28: REQ027 | B28: Deloitte | C28: Consulting | D28: MIS Analyst | E28: Mid | F28: Kavitha M | G28: West | H28: Referral | I28: 2025-03-18 | J28: 2025-03-21 | K28: 2025-03-26 | L28: 2025-03-30 | M28: 2025-04-07 | N28: Arun M | O28: Male | P28: 3 | Q28: 5.5 | R28: 6.5 | S28: 6.5 | T28: Pune | U28: Selected | V28: Accepted | W28: Joined | X28: 15 | Y28: 19 | Z28: =TEXT(Table1[[#This Row],[Date_Sourced]],"mmm - YYYY") -> Mar - 2025 | AA28: =TEXT(Table1[[#This Row],[Date_Joined]],"mmm - YYYY") -> Apr - 2025
A29: REQ028 | B29: Infosys | C29: IT Services | D29: Data Engineer | E29: Senior | F29: Ramesh Gupta | G29: North | H29: LinkedIn | I29: 2025-03-20 | J29: 2025-03-23 | K29: 2025-03-28 | N29: Sujatha K | O29: Female | P29: 5 | Q29: 12 | R29: 14 | S29: 0 | T29: Bangalore | U29: Rejected | W29: Not Joined | X29: 60 | Y29: 0 | Z29: =TEXT(Table1[[#This Row],[Date_Sourced]],"mmm - YYYY") -> Mar - 2025 | AA29: =TEXT(Table1[[#This Row],[Date_Joined]],"mmm - YYYY") -> Jan - 1900
A30: REQ029 | B30: HCL | C30: IT Services | D30: Data Analyst | E30: Junior | F30: Anitha R | G30: South | H30: Walk-In | I30: 2025-03-22 | J30: 2025-03-25 | K30: 2025-03-30 | L30: 2025-04-03 | M30: 2025-04-10 | N30: Rajan T | O30: Male | P30: 1 | Q30: 3 | R30: 4 | S30: 4 | T30: Tiruchirappalli | U30: Selected | V30: Accepted | W30: Joined | X30: 0 | Y30: 19 | Z30: =TEXT(Table1[[#This Row],[Date_Sourced]],"mmm - YYYY") -> Mar - 2025 | AA30: =TEXT(Table1[[#This Row],[Date_Joined]],"mmm - YYYY") -> Apr - 2025
A31: REQ030 | B31: Wipro | C31: IT Services | D31: MIS Analyst | E31: Mid | F31: Senthil Kumar | G31: South | H31: Naukri | I31: 2025-03-25 | J31: 2025-03-28 | K31: 2025-04-02 | N31: Nirmala P | O31: Female | P31: 2 | Q31: 4 | R31: 5 | S31: 0 | T31: Chennai | U31: In-Progress | V31: Pending | W31: Not Joined | X31: 30 | Y31: 0 | Z31: =TEXT(Table1[[#This Row],[Date_Sourced]],"mmm - YYYY") -> Mar - 2025 | AA31: =TEXT(Table1[[#This Row],[Date_Joined]],"mmm - YYYY") -> Jan - 1900
A32: REQ031 | B32: Accenture | C32: Consulting | D32: Business Analyst | E32: Senior | F32: Kavitha M | G32: West | H32: LinkedIn | I32: 2025-04-02 | J32: 2025-04-05 | K32: 2025-04-10 | L32: 2025-04-14 | M32: 2025-04-21 | N32: Sunil R | O32: Male | P32: 5 | Q32: 8 | R32: 10 | S32: 10 | T32: Mumbai | U32: Selected | V32: Accepted | W32: Joined | X32: 45 | Y32: 19 | Z32: =TEXT(Table1[[#This Row],[Date_Sourced]],"mmm - YYYY") -> Apr - 2025 | AA32: =TEXT(Table1[[#This Row],[Date_Joined]],"mmm - YYYY") -> Apr - 2025
A33: REQ032 | B33: Cognizant | C33: IT Services | D33: Data Analyst | E33: Mid | F33: Senthil Kumar | G33: South | H33: LinkedIn | I33: 2025-04-05 | J33: 2025-04-08 | K33: 2025-04-13 | L33: 2025-04-17 | M33: 2025-04-23 | N33: Geetha M | O33: Female | P33: 3 | Q33: 5.5 | R33: 7 | S33: 7 | T33: Bangalore | U33: Selected | V33: Accepted | W33: Joined | X33: 15 | Y33: 18 | Z33: =TEXT(Table1[[#This Row],[Date_Sourced]],"mmm - YYYY") -> Apr - 2025 | AA33: =TEXT(Table1[[#This Row],[Date_Joined]],"mmm - YYYY") -> Apr - 2025
A34: REQ033 | B34: TCS | C34: IT Services | D34: Reporting Analyst | E34: Junior | F34: Anitha R | G34: South | H34: Naukri | I34: 2025-04-08 | J34: 2025-04-11 | K34: 2025-04-16 | N34: Muthu K | O34: Male | P34: 1 | Q34: 2.5 | R34: 3.5 | S34: 0 | T34: Madurai | U34: Rejected | W34: Not Joined | X34: 30 | Y34: 0 | Z34: =TEXT(Table1[[#This Row],[Date_Sourced]],"mmm - YYYY") -> Apr - 2025 | AA34: =TEXT(Table1[[#This Row],[Date_Joined]],"mmm - YYYY") -> Jan - 1900
A35: REQ034 | B35: HCL | C35: IT Services | D35: Data Engineer | E35: Senior | F35: Ramesh Gupta | G35: North | H35: LinkedIn | I35: 2025-04-10 | J35: 2025-04-13 | K35: 2025-04-18 | L35: 2025-04-22 | M35: 2025-04-29 | N35: Pavithra S | O35: Female | P35: 6 | Q35: 13 | R35: 16 | S35: 15.5 | T35: Hyderabad | U35: Selected | V35: Accepted | W35: Joined | X35: 60 | Y35: 19 | Z35: =TEXT(Table1[[#This Row],[Date_Sourced]],"mmm - YYYY") -> Apr - 2025 | AA35: =TEXT(Table1[[#This Row],[Date_Joined]],"mmm - YYYY") -> Apr - 2025
A36: REQ035 | B36: Deloitte | C36: Consulting | D36: Data Scientist | E36: Senior | F36: Kavitha M | G36: West | H36: LinkedIn | I36: 2025-04-12 | J36: 2025-04-15 | K36: 2025-04-20 | N36: Kiran B | O36: Male | P36: 5 | Q36: 14 | R36: 17 | S36: 0 | T36: Pune | U36: Rejected | W36: Not Joined | X36: 30 | Y36: 0 | Z36: =TEXT(Table1[[#This Row],[Date_Sourced]],"mmm - YYYY") -> Apr - 2025 | AA36: =TEXT(Table1[[#This Row],[Date_Joined]],"mmm - YYYY") -> Jan - 1900
A37: REQ036 | B37: Wipro | C37: IT Services | D37: MIS Analyst | E37: Junior | F37: Anitha R | G37: South | H37: Walk-In | I37: 2025-04-15 | J37: 2025-04-18 | K37: 2025-04-23 | L37: 2025-04-27 | M37: 2025-05-04 | N37: Saranya V | O37: Female | P37: 1 | Q37: 3 | R37: 3.5 | S37: 3.5 | T37: Chennai | U37: Selected | V37: Accepted | W37: Joined | X37: 0 | Y37: 19 | Z37: =TEXT(Table1[[#This Row],[Date_Sourced]],"mmm - YYYY") -> Apr - 2025 | AA37: =TEXT(Table1[[#This Row],[Date_Joined]],"mmm - YYYY") -> May - 2025
A38: REQ037 | B38: Infosys | C38: IT Services | D38: Data Analyst | E38: Mid | F38: Senthil Kumar | G38: South | H38: Referral | I38: 2025-04-18 | J38: 2025-04-21 | K38: 2025-04-26 | L38: 2025-04-30 | M38: 2025-05-07 | N38: Bharath M | O38: Male | P38: 3 | Q38: 5 | R38: 6.5 | S38: 6.5 | T38: Bangalore | U38: Selected | V38: Accepted | W38: Joined | X38: 15 | Y38: 19 | Z38: =TEXT(Table1[[#This Row],[Date_Sourced]],"mmm - YYYY") -> Apr - 2025 | AA38: =TEXT(Table1[[#This Row],[Date_Joined]],"mmm - YYYY") -> May - 2025
A39: REQ038 | B39: Accenture | C39: Consulting | D39: Business Analyst | E39: Mid | F39: Kavitha M | G39: West | H39: LinkedIn | I39: 2025-04-20 | J39: 2025-04-23 | K39: 2025-04-28 | N39: Hema R | O39: Female | P39: 4 | Q39: 6.5 | R39: 8.5 | S39: 0 | T39: Mumbai | U39: In-Progress | V39: Pending | W39: Not Joined | X39: 45 | Y39: 0 | Z39: =TEXT(Table1[[#This Row],[Date_Sourced]],"mmm - YYYY") -> Apr - 2025 | AA39: =TEXT(Table1[[#This Row],[Date_Joined]],"mmm - YYYY") -> Jan - 1900
A40: REQ039 | B40: Cognizant | C40: IT Services | D40: Data Engineer | E40: Senior | F40: Ramesh Gupta | G40: North | H40: LinkedIn | I40: 2025-04-22 | J40: 2025-04-25 | K40: 2025-04-30 | L40: 2025-05-04 | M40: 2025-05-12 | N40: Naveen S | O40: Male | P40: 5 | Q40: 11 | R40: 14 | S40: 13.5 | T40: Hyderabad | U40: Selected | V40: Accepted | W40: Joined | X40: 30 | Y40: 20 | Z40: =TEXT(Table1[[#This Row],[Date_Sourced]],"mmm - YYYY") -> Apr - 2025 | AA40: =TEXT(Table1[[#This Row],[Date_Joined]],"mmm - YYYY") -> May - 2025
...

Sheet Summary_Metrics
A1: 📊 Summary Metrics — Formulas from Raw_Data
B3: 📌 TOP-LINE KPIs (BQ1 — Hiring Funnel)
B4: KPI | C4: Your Answer
B5: Total Requisitions | C5: =COUNTA(Raw_Data!A2:A51) -> 50
B6: Total Interviewed | C6: =COUNTIF(Raw_Data!K3:K51,"<>""") -> 49
B7: Total Selected | C7: =COUNTIF(Table1[Interview_Status],"Selected") -> 27
B8: Offers Accepted | C8: =COUNTIF(Table1[Offer_Status],"Accepted") -> 27
B9: Total Joined | C9: =COUNTIF(Table1[Joining_Status],"Joined") -> 27
B10: Overall Conversion % | C10: =COUNTIF(Table1[Joining_Status],"Joined")/COUNTA(Table1[Req_ID]) -> 0.54 | D10: (format as %)
B11: Avg TAT (Joined only) | C11: =ROUND(AVERAGEIF(Table1[Joining_Status],"Joined",Table1[TAT_Days]),2) -> 18.59 | D11: days
B12: Avg Offered CTC | C12: =AVERAGEIF(Table1[Offer_Status],"Accepted",Table1[Offered_CTC_LPA]) -> 8.6481481 | D12: LPA
B15: 👥 RECRUITER PERFORMANCE (BQ2)
B16: Recruiter Name | C16: Total Reqs | D16: Placements (Joined) | E16: Conversion % | F16: Avg TAT (days)
B17: Senthil Kumar | C17: =COUNTIF(Table1[Recruiter_Name],B17) -> 16 | D17: =COUNTIFS(Table1[Recruiter_Name],Summary_Metrics!B17,Table1[Joining_Status],"Joined") -> 8 | E17: =D17/COUNTA(Raw_Data!$A$2:$A$51) * 100 & " %" -> 16 % | F17: =ROUND(AVERAGEIFS(Table1[TAT_Days],Table1[Recruiter_Name],Summary_Metrics!B17,Table1[TAT_Days],">0"),2) -> 17.5
B18: Anitha R | C18: =COUNTIF(Table1[Recruiter_Name],B18) -> 13 | D18: =COUNTIFS(Table1[Recruiter_Name],Summary_Metrics!B18,Table1[Joining_Status],"Joined") -> 5 | E18: =D18/COUNTA(Raw_Data!$A$2:$A$51) * 100 & " %" -> 10 % | F18: =ROUND(AVERAGEIFS(Table1[TAT_Days],Table1[Recruiter_Name],Summary_Metrics!B18,Table1[TAT_Days],">0"),2) -> 18.8
B19: Ramesh Gupta | C19: =COUNTIF(Table1[Recruiter_Name],B19) -> 9 | D19: =COUNTIFS(Table1[Recruiter_Name],Summary_Metrics!B19,Table1[Joining_Status],"Joined") -> 6 | E19: =D19/COUNTA(Raw_Data!$A$2:$A$51) * 100 & " %" -> 12 % | F19: =ROUND(AVERAGEIFS(Table1[TAT_Days],Table1[Recruiter_Name],Summary_Metrics!B19,Table1[TAT_Days],">0"),2) -> 19.33
B20: Kavitha M | C20: =COUNTIF(Table1[Recruiter_Name],B20) -> 12 | D20: =COUNTIFS(Table1[Recruiter_Name],Summary_Metrics!B20,Table1[Joining_Status],"Joined") -> 8 | E20: =D20/COUNTA(Raw_Data!$A$2:$A$51) * 100 & " %" -> 16 % | F20: =ROUND(AVERAGEIFS(Table1[TAT_Days],Table1[Recruiter_Name],Summary_Metrics!B20,Table1[TAT_Days],">0"),2) -> 19
B22: 📡 SOURCING CHANNEL ROI (BQ3)
B23: Channel | C23: Total Sourced | D23: Joined | E23: Conversion %
B24: LinkedIn | C24: =COUNTIF(Table1[Sourcing_Channel],Summary_Metrics!B24) -> 24 | D24: =COUNTIFS(Table1[Sourcing_Channel],Summary_Metrics!B24,Table1[Joining_Status],"Joined") -> 18 | E24: =D24/C24*100&"%" -> 75%
B25: Naukri | C25: =COUNTIF(Table1[Sourcing_Channel],Summary_Metrics!B25) -> 12 | D25: =COUNTIFS(Table1[Sourcing_Channel],Summary_Metrics!B25,Table1[Joining_Status],"Joined") -> 2 | E25: =D25/C25*100&"%" -> 16.6666666666667%
B26: Referral | C26: =COUNTIF(Table1[Sourcing_Channel],Summary_Metrics!B26) -> 7 | D26: =COUNTIFS(Table1[Sourcing_Channel],Summary_Metrics!B26,Table1[Joining_Status],"Joined") -> 4 | E26: =D26/C26*100&"%" -> 57.1428571428571%
B27: Walk-In | C27: =COUNTIF(Table1[Sourcing_Channel],Summary_Metrics!B27) -> 7 | D27: =COUNTIFS(Table1[Sourcing_Channel],Summary_Metrics!B27,Table1[Joining_Status],"Joined") -> 3 | E27: =D27/C27*100&"%" -> 42.8571428571429%
B29: 📅 MONTHLY HIRING TREND (BQ4)
B30: Month | C30: Total Sourced | D30: Joined
B31: Jan-2025 | C31: =COUNTIF(Table1[sourced_month],Summary_Metrics!B31) -> 10 | D31: =COUNTIF(Table1[Joined_month],Summary_Metrics!B31) -> 2
B32: Feb-2025 | C32: =COUNTIF(Table1[sourced_month],"Jan 2025") -> 10 | D32: =COUNTIF(Table1[Joined_month],Summary_Metrics!B32) -> 5
B33: Mar-2025 | C33: =COUNTIF(Table1[sourced_month],"Jan 2025") -> 10 | D33: =COUNTIF(Table1[Joined_month],Summary_Metrics!B33) -> 5
B34: Apr-2025 | C34: =COUNTIF(Table1[sourced_month],"Jan 2025") -> 10 | D34: =COUNTIF(Table1[Joined_month],Summary_Metrics!B34) -> 6
B35: May-2025 | C35: =COUNTIF(Table1[sourced_month],"Jan 2025") -> 10 | D35: =COUNTIF(Table1[Joined_month],Summary_Metrics!B35) -> 6
B36: Jun-2025 | C36: =COUNTIF(Table1[sourced_month],"Jan 2025") -> 10 | D36: =COUNTIF(Table1[Joined_month],Summary_Metrics!B36) -> 3
B38: 💰 CTC GAP ANALYSIS (BQ5)
B39: Role | C39: Avg Expected CTC | D39: Avg Offered CTC | E39: Gap (Expected - Offered)
B40: Data Analyst | C40: =ROUND(AVERAGEIF(Table1[Role],Summary_Metrics!B40,Table1[Expected_CTC_LPA]),2) -> 6.75 | D40: =ROUND(IFERROR(AVERAGEIFS(Table1[Offered_CTC_LPA],Table1[Role],Summary_Metrics!B40,Table1[Offer_Status],"Accepted"),C40),2) -> 6.96 | E40: =C40-D40 -> -0.21
B41: MIS Analyst | C41: =ROUND(AVERAGEIF(Table1[Role],Summary_Metrics!B41,Table1[Expected_CTC_LPA]),2) -> 4.68 | D41: =ROUND(IFERROR(AVERAGEIFS(Table1[Offered_CTC_LPA],Table1[Role],Summary_Metrics!B41,Table1[Offer_Status],"Accepted"),C41),2) -> 4.5 | E41: =C41-D41 -> 0.18
B42: Business Analyst | C42: =ROUND(AVERAGEIF(Table1[Role],Summary_Metrics!B42,Table1[Expected_CTC_LPA]),2) -> 8.07 | D42: =ROUND(IFERROR(AVERAGEIFS(Table1[Offered_CTC_LPA],Table1[Role],Summary_Metrics!B42,Table1[Offer_Status],"Accepted"),C42),2) -> 8.13 | E42: =C42-D42 -> -0.06
B43: Data Engineer | C43: =ROUND(AVERAGEIF(Table1[Role],Summary_Metrics!B43,Table1[Expected_CTC_LPA]),2) -> 14.14 | D43: =ROUND(IFERROR(AVERAGEIFS(Table1[Offered_CTC_LPA],Table1[Role],Summary_Metrics!B43,Table1[Offer_Status],"Accepted"),C43),2) -> 13.75 | E43: =C43-D43 -> 0.39
B44: Data Scientist | C44: =ROUND(AVERAGEIF(Table1[Role],Summary_Metrics!B44,Table1[Expected_CTC_LPA]),2) -> 16 | D44: =ROUND(IFERROR(AVERAGEIFS(Table1[Offered_CTC_LPA],Table1[Role],Summary_Metrics!B44,Table1[Offer_Status],"Accepted"),C44),2) -> 16 | E44: =C44-D44 -> 0
B45: Reporting Analyst | C45: =ROUND(AVERAGEIF(Table1[Role],Summary_Metrics!B45,Table1[Expected_CTC_LPA]),2) -> 4 | D45: =ROUND(IFERROR(AVERAGEIFS(Table1[Offered_CTC_LPA],Table1[Role],Summary_Metrics!B45,Table1[Offer_Status],"Accepted"),C45),2) -> 4 | E45: =C45-D45 -> 0

Sheet Dashboard
A1: 📊 V-Dart Recruitment MIS Dashboard | Jan – Jun 2025
B3: Total Reqs | D3: Placed | F3: Conversion % | H3: Avg TAT (Days) | J3: Avg Offered CTC
B4: =Summary_Metrics!C5 -> 50 | D4: =Summary_Metrics!C9 -> 27 | F4: =Summary_Metrics!C10 -> 0.54 | H4: =Summary_Metrics!C11 -> 18.59 | J4: =Summary_Metrics!C12 -> 8.6481481
B6: 📈 BQ1 — Hiring Funnel Chart (Bar chart: Total→Interviewed→Selected→Offered→Joined) Create from Summary_Metrics KPI table | H6: 👥 BQ2 — Recruiter Performance Chart (Clustered bar: Recruiter vs Placements vs Conversion%) Create from Summary_Metrics Recruiter table
B18: 📡 BQ3 — Channel ROI Chart (Clustered bar: Channel vs Sourced vs Joined) Create from Summary_Metrics Channel table | H18: 📅 BQ4 — Monthly Trend Chart (Line chart: Month vs Sourced vs Joined) Create from Summary_Metrics Monthly table
B30: 💰 BQ5 — CTC Gap Analysis Chart (Grouped bar: Role vs Avg Expected vs Avg Offered) Create from Summary_Metrics CTC Gap table Add conditional formatting: Red if Gap > 1 LPA
